<?xml version="1.0" encoding="utf-8"?>
<!-- This URDF was automatically created by SolidWorks to URDF Exporter! -->

<robot name="spherical_arm">

<material name="dark_grey">
  <color rgba="0.3 0.3 0.3 1" />
</material>

<material name="white">
  <color rgba="1 1 1 1" />
</material>

<material name="neon_orange">
  <color rgba="1 0.5 0 1" />
</material>
<!-- Link: Leg1 -->
<link name="Leg1">
  <inertial>
    <origin xyz="0 0 0" rpy="0 0 0" />
    <mass value="0.5" />
    <inertia ixx="0.01" ixy="0" ixz="0" iyy="0.01" iyz="0" izz="0.01" />
  </inertial>
  <visual>
    <origin xyz="0 0 -0.25" rpy="0 0 0" />
    <geometry>
      <cylinder radius="0.05" length="0.5" />
    </geometry>
    <material name="dark_grey" />
  </visual>
  <collision>
    <origin xyz="0 0 -0.25" rpy="0 0 0" />
    <geometry>
      <cylinder radius="0.05" length="0.5" />
    </geometry>
  </collision>
</link>
<link name="Leg2">
  <inertial>
    <origin xyz="0 0 0" rpy="0 0 0" />
    <mass value="0.5" />
    <inertia ixx="0.01" ixy="0" ixz="0" iyy="0.01" iyz="0" izz="0.01" />
  </inertial>
  <visual>
    <origin xyz="0 0 -0.25" rpy="0 0 0" />
    <geometry>
      <cylinder radius="0.05" length="0.5" />
    </geometry>
    <material name="dark_grey" />
  </visual>
  <collision>
    <origin xyz="0 0 -0.25" rpy="0 0 0" />
    <geometry>
      <cylinder radius="0.05" length="0.5" />
    </geometry>
  </collision>
</link>
<link name="Leg3">
  <inertial>
    <origin xyz="0 0 0" rpy="0 0 0" />
    <mass value="0.5" />
    <inertia ixx="0.01" ixy="0" ixz="0" iyy="0.01" iyz="0" izz="0.01" />
  </inertial>
  <visual>
    <origin xyz="0 0 -0.25" rpy="0 0 0" />
    <geometry>
      <cylinder radius="0.05" length="0.5" />
    </geometry>
    <material name="dark_grey" />
  </visual>
  <collision>
    <origin xyz="0 0 -0.25" rpy="0 0 0" />
    <geometry>
      <cylinder radius="0.05" length="0.5" />
    </geometry>
  </collision>
</link>
<link name="Leg4">
  <inertial>
    <origin xyz="0 0 0" rpy="0 0 0" />
    <mass value="0.5" />
    <inertia ixx="0.01" ixy="0" ixz="0" iyy="0.01" iyz="0" izz="0.01" />
  </inertial>
  <visual>
    <origin xyz="0 0 -0.25" rpy="0 0 0" />
    <geometry>
      <cylinder radius="0.05" length="0.5" />
    </geometry>
    <material name="dark_grey" />
  </visual>
  <collision>
    <origin xyz="0 0 -0.25" rpy="0 0 0" />
    <geometry>
      <cylinder radius="0.05" length="0.5" />
    </geometry>
  </collision>
</link>
<!-- Joint: Table_to_Leg1 -->
<joint name="Table_to_Leg1" type="fixed">
  <origin xyz="0.45 0.95 -0.025" rpy="0 0 0" />
  <parent link="Table" />
  <child link="Leg1" />
</joint>

<!-- Joint: Table_to_Leg2 -->
<joint name="Table_to_Leg2" type="fixed">
  <origin xyz="-0.45 0.95 -0.025" rpy="0 0 0" />
  <parent link="Table" />
  <child link="Leg2" />
</joint>

<!-- Joint: Table_to_Leg3 -->
<joint name="Table_to_Leg3" type="fixed">
  <origin xyz="0.45 -0.95 -0.025" rpy="0 0 0" />
  <parent link="Table" />
  <child link="Leg3" />
</joint>

<!-- Joint: Table_to_Leg4 -->
<joint name="Table_to_Leg4" type="fixed">
  <origin xyz="-0.45 -0.95 -0.025" rpy="0 0 0" />
  <parent link="Table" />
  <child link="Leg4" />
</joint>

<!-- Link: Table -->
<link name="Table">
  <inertial>
    <origin xyz="0 0 0" rpy="0 0 0" />
    <mass value="5.0" />
    <inertia ixx="0.1" ixy="0" ixz="0" iyy="0.1" iyz="0" izz="0.1" />
  </inertial>
  <visual>
    <origin xyz="0 0 0" rpy="0 0 0" />
    <geometry>
      <box size="1 2 0.05" />
    </geometry>
<material name="white">
  <color rgba="1 1 1 1" />
</material>

  </visual>
  <collision>
    <origin xyz="0 0 0" rpy="0 0 0" />
    <geometry>
      <box size="0.5 0.5 0.05" />
    </geometry>
  </collision>
</link>

<joint name="Clamp_to_Table" type="fixed">
  <origin xyz="-0.5 -0.3 +0.01" rpy="0 0 0" />
  <parent link="Clamp" />
  <child link="Table" />
</joint>

 <!-- Root Link: Clamp -->
<link name="Clamp">
  <visual>
    <origin xyz="0 0 0" rpy="0 0 0" />
    <geometry>
      <mesh filename="package://spherical_arm/meshes/Clamp.STL" />
    </geometry>
<material name="neon_orange">
  <color rgba="1 0.5 0 1" />
</material>
  </visual>
  <collision>
    <origin xyz="0 0 0" rpy="0 0 0" />
    <geometry>
      <mesh filename="package://spherical_arm/meshes/Clamp.STL" />
    </geometry>
  </collision>
</link>

  <!-- Link: BaseBottom -->
  <link name="BaseBottom">
    <inertial>
      <origin xyz="0.027516 0.014617 -5.3932E-08" rpy="0 0 0" />
      <mass value="0.10485" />
      <inertia ixx="7.271E-05" ixy="-1.7562E-05" ixz="3.3609E-12" iyy="0.00011017" iyz="-4.0092E-11" izz="7.6148E-05" />
    </inertial>
    <visual>
      <origin xyz="0 0 0" rpy="1.5708 0 0" />
      <geometry>
        <mesh filename="package://spherical_arm/meshes/BaseBottom.STL" />
      </geometry>
<material name="neon_orange">
  <color rgba="1 0.5 0 1" />
</material>
    </visual>
    <collision>
      <origin xyz="0 0 0" rpy="0 0 0" />
      <geometry>
        <mesh filename="package://spherical_arm/meshes/BaseBottom.STL" />
      </geometry>
    </collision>
  </link>

  <!-- Joint: BaseCoincident -->
  <joint name="BaseCoincident" type="fixed">
    <origin xyz="-0.042533 -0.12096 0.069938" rpy="0 0 0" />
    <parent link="Clamp" />
    <child link="BaseBottom" />
    <axis xyz="0 0 0" />
  </joint>

  <!-- Link: Basetop -->
  <link name="Basetop">
    <inertial>
      <origin xyz="0.017744 0.050216 5.5971E-08" rpy="0 0 0" />
      <mass value="0.061686" />
      <inertia ixx="3.3277E-05" ixy="3.1323E-06" ixz="6.4171E-11" iyy="6.5761E-05" iyz="5.3966E-12" izz="3.5972E-05" />
    </inertial>
    <visual>
      <origin xyz="0 0 0" rpy="0 0 0" />
      <geometry>
        <mesh filename="package://spherical_arm/meshes/Basetop.STL" />
      </geometry>
<material name="neon_orange">
  <color rgba="1 0.5 0 1" />
</material>
    </visual>
    <collision>
      <origin xyz="0 0 0" rpy="0 0 0" />
      <geometry>
        <mesh filename="package://spherical_arm/meshes/Basetop.STL" />
      </geometry>
    </collision>
  </link>

  <!-- Joint: Basetop_coincident -->
  <joint name="Basetop_coincident" type="fixed">
    <origin xyz="0 0 0" rpy="1.5708 0 0" />
    <parent link="BaseBottom" />
    <child link="Basetop" />
    <axis xyz="0 0 0" />
  </joint>

  <!-- Link: Link1 -->
  <link name="Link1">
    <inertial>
      <origin xyz="-0.073232 -0.1745 0.015767" rpy="0 0 0" />
      <mass value="0.13439" />
      <inertia ixx="7.1758E-05" ixy="0.00011693" ixz="3.8198E-07" iyy="0.00034167" iyz="8.0268E-07" izz="0.00038897" />
    </inertial>
    <visual>
      <origin xyz="0 0 0" rpy="0 0 0" />
      <geometry>
        <mesh filename="package://spherical_arm/meshes/Link1.STL" />
      </geometry>
<material name="dark_grey">
  <color rgba="0.3 0.3 0.3 1" />
</material>
    </visual>
    <collision>
      <origin xyz="0 0 0" rpy="0 0 0" />
      <geometry>
        <mesh filename="package://spherical_arm/meshes/Link1.STL" />
      </geometry>
    </collision>
  </link>

  <!-- Joint: Base_Revolute -->
  <joint name="Base_Revolute" type="revolute">
    <origin xyz="-0.011931 0.2308 -0.014931" rpy="0 0.12246 0" />
    <parent link="Basetop" />
    <child link="Link1" />
    <axis xyz="0 1 0" />
    <limit lower="-1.57" upper="1.57" effort="10" velocity="1" />
  </joint>

  <!-- Link: Link2 -->
  <link name="Link2">
    <inertial>
      <origin xyz="-0.14211 -0.03561 0.00027708" rpy="0 0 0" />
      <mass value="0.14126" />
      <inertia ixx="0.00022787" ixy="8.7681E-05" ixz="1.3203E-07" iyy="0.00010115" iyz="8.5903E-07" izz="0.00030502" />
    </inertial>
    <visual>
      <origin xyz="0 0 0" rpy="0 0 0" />
      <geometry>
        <mesh filename="package://spherical_arm/meshes/Link2.STL" />
      </geometry>
<material name="dark_grey">
  <color rgba="0.3 0.3 0.3 1" />
</material>
    </visual>
    <collision>
      <origin xyz="0 0 0" rpy="0 0 0" />
      <geometry>
        <mesh filename="package://spherical_arm/meshes/Link2.STL" />
      </geometry>
    </collision>
  </link>

  <!-- Joint: Revolute_2 -->
  <joint name="Revolute_2" type="revolute">
    <origin xyz="-0.033505 -0.033505 0.015" rpy="0.34542 0.32648 0.057449" />
    <parent link="Link1" />
    <child link="Link2" />
    <axis xyz="0.70711 0.70711 0" />
    <limit lower="-1.57" upper="1.57" effort="10" velocity="1" />
  </joint>

  <!-- Link: Link3 -->
  <link name="Link3">
    <inertial>
      <origin xyz="-0.15007 -0.043098 1.8252E-06" rpy="0 0 0" />
      <mass value="0.14347" />
      <inertia ixx="0.00022731" ixy="9.6672E-05" ixz="3.6072E-09" iyy="0.00015405" iyz="-3.4694E-09" izz="0.0003606" />
    </inertial>
    <visual>
      <origin xyz="0 0 0" rpy="0 0 0" />
      <geometry>
        <mesh filename="package://spherical_arm/meshes/Link3.STL" />
      </geometry>
<material name="dark_grey">
  <color rgba="0.3 0.3 0.3 1" />
</material>
    </visual>
    <collision>
      <origin xyz="0 0 0" rpy="0 0 0" />
      <geometry>
        <mesh filename="package://spherical_arm/meshes/Link3.STL" />
      </geometry>
    </collision>
  </link>

  <!-- Joint: Revolute3 -->
  <joint name="Revolute3" type="revolute">
    <origin xyz="0 0.033257 0" rpy="-0.13898 -0.13765 -0.7758" />
    <parent link="Link2" />
    <child link="Link3" />
    <axis xyz="0.70711 0.70711 0" />
    <limit lower="-1.57" upper="1.57" effort="10" velocity="1" />
  </joint>

</robot>