<?xml version="1.0" encoding="utf-8" ?>
<robot name="spherical_manipulator">
    <!-- Base Link -->
    <link name="base">
        <inertial>
            <origin xyz="-0.015 0.015 0.00273" rpy="0.0 0.0 0.0" />
            <mass value="50.036157" />
            <inertia ixx="2.82e-03" iyy="2.82e-03" izz="5.3e-03" ixy="0.0" iyz="0.0" ixz="0.0" />
        </inertial>
        <visual>
            <origin xyz="0.0 0.0 0.0" rpy="0.0 0.0 0.0" />
            <geometry>
                <mesh filename="package://my_spherical_manipulator/meshes/base.stl" scale="0.001 0.001 0.001" />
            </geometry>
        </visual>
        <collision>
            <origin xyz="0.0 0.0 0.0" rpy="0.0 0.0 0.0" />
            <geometry>
                <mesh filename="package://my_spherical_manipulator/meshes/base.stl" scale="0.001 0.001 0.001" />
            </geometry>
        </collision>
        <!-- Gazebo-specific properties -->
        <gazebo>
            <material>Gazebo/Blue</material>
        </gazebo>
    </link>
    <!-- Small Link -->
    <link name="small">
        <inertial>
            <origin xyz="-0.0154 -0.01326 -0.00339" rpy="0.0 0.0 0.0" />
            <mass value="0.0372" />
            <inertia ixx="4.05e-03" iyy="4.0e-03" izz="7.31e-03" ixy="0.0" iyz="0.0" ixz="0.0" />
        </inertial>
        <visual>
            <origin xyz="-0.03017 0.0035 -0.05223" rpy="0.3729 1.0069 2.8111" />
            <geometry>
                <mesh filename="package://my_spherical_manipulator/meshes/small.stl" scale="0.001 0.001 0.001" />
            </geometry>
        </visual>
        <collision>
            <origin xyz="-0.03017 0.0035 -0.05223" rpy="0.3729 1.0069 2.8111" />
            <geometry>
                <mesh filename="package://my_spherical_manipulator/meshes/small.stl" scale="0.001 0.001 0.001" />
            </geometry>
        </collision>
    </link>
    <!-- Medium Link -->
    <link name="medium">
        <inertial>
            <origin xyz="0.00104 -0.02517 0.0023" rpy="0.0 0.0 0.0" />
            <mass value="0.0447" />
            <inertia ixx="1.235e-02" iyy="1.28e-03" izz="1.19e-02" ixy="0.0" iyz="0.0" ixz="0.0" />
        </inertial>
        <visual>
            <origin xyz="-0.00343 -0.03421 -0.04968" rpy="1.2088 1.0221 -1.8593" />
            <geometry>
                <mesh filename="package://my_spherical_manipulator/meshes/medium.stl" scale="0.001 0.001 0.001" />
            </geometry>
        </visual>
        <collision>
            <origin xyz="-0.00343 -0.03421 -0.04968" rpy="1.2088 1.0221 -1.8593" />
            <geometry>
                <mesh filename="package://my_spherical_manipulator/meshes/medium.stl" scale="0.001 0.001 0.001" />
            </geometry>
        </collision>
    </link>
    <!-- Large Link -->
    <link name="large">
        <inertial>
            <origin xyz="0.01046 -0.02854 0.01198" rpy="0.0 0.0 0.0" />
            <mass value="0.0598" />
            <inertia ixx="2.58e-02" iyy="1.05e-02" izz="2.1e-02" ixy="0.0" iyz="0.0" ixz="0.0" />
        </inertial>
        <visual>
            <origin xyz="-0.00297 -0.006415 0.056" rpy="-2.79 -1.57 0.0" />
            <geometry>
                <mesh filename="package://my_spherical_manipulator/meshes/large.stl" scale="0.001 0.001 0.001" />
            </geometry>
        </visual>
        <collision>
            <origin xyz="-0.00297 -0.006415 0.056" rpy="-2.79 -1.57 0.0" />
            <geometry>
                <mesh filename="package://my_spherical_manipulator/meshes/large.stl" scale="0.001 0.001 0.001" />
            </geometry>
        </collision>
    </link>
    <!-- Joints -->
    <joint name="base_Revolute_1" type="continuous">
        <origin xyz="-0.015 0.015 0.02" rpy="0.0 0.0 0.0" />
        <parent link="base" />
        <child link="large" />
        <axis xyz="0.0 0.0 1.0" />
        <limit effort="300" velocity="1.0" />
        <dynamics damping="0.1" friction="0.1" />
    </joint>
    <joint name="large_Revolute_2" type="continuous">
        <origin xyz="0.01749 -0.0477 0.03533" rpy="-1.57 0.0 -2.618" />
        <parent link="large" />
        <child link="medium" />
        <axis xyz="-0.148 -0.5 -0.853" />
        <limit effort="300" velocity="1.0" />
        <dynamics damping="0.1" friction="0.1" />
    </joint>
    <joint name="medium_Revolute_3" type="continuous">
        <origin xyz="0.0009125 -0.04792 -0.001272" rpy="0.0 -0.349 0.0" />
        <parent link="medium" />
        <child link="small" />
        <axis xyz="-0.506 0.173 -0.845" />
        <limit effort="300" velocity="1.0" />
        <dynamics damping="0.1" friction="0.1" />
    </joint>
    <!-- Transmissions -->
    <transmission name="base_Revolute_1_trans">
        <type>transmission_interface/SimpleTransmission</type>
        <joint name="base_Revolute_1">
            <hardwareInterface>hardware_interface/PositionJointInterface</hardwareInterface>
        </joint>
        <actuator name="base_Revolute_1_motor">
            <mechanicalReduction>1</mechanicalReduction>
            <hardwareInterface>hardware_interface/PositionJointInterface</hardwareInterface>
        </actuator>
    </transmission>
    <transmission name="large_Revolute_2_trans">
        <type>transmission_interface/SimpleTransmission</type>
        <joint name="large_Revolute_2">
            <hardwareInterface>hardware_interface/PositionJointInterface</hardwareInterface>
        </joint>
        <actuator name="large_Revolute_2_motor">
            <mechanicalReduction>1</mechanicalReduction>
            <hardwareInterface>hardware_interface/PositionJointInterface</hardwareInterface>
        </actuator>
    </transmission>
    <transmission name="medium_Revolute_3_trans">
        <type>transmission_interface/SimpleTransmission</type>
        <joint name="medium_Revolute_3">
            <hardwareInterface>hardware_interface/PositionJointInterface</hardwareInterface>
        </joint>
        <actuator name="medium_Revolute_3_motor">
            <mechanicalReduction>1</mechanicalReduction>
            <hardwareInterface>hardware_interface/PositionJointInterface</hardwareInterface>
        </actuator>
    </transmission>
    <gazebo>
        <plugin name="gazebo_ros_control" filename="libgazebo_ros_control.so">
            <robotNamespace>/</robotNamespace>
        </plugin>
    </gazebo>
</robot>

